<?xml version="1.0" ?>
<!-- =================================================================================== -->
<!-- |    This document was autogenerated by xacro from omnihand_right.xacro           | -->
<!-- |    EDITING THIS FILE BY HAND IS NOT RECOMMENDED                                 | -->
<!-- =================================================================================== -->
<robot name="omnihand">
  <!-- joint position value -->
  <material name="black">
    <color rgba="0.0 0.0 0.0 1.0"/>
  </material>
  <material name="blue">
    <color rgba="0.0 0.0 0.8 1.0"/>
  </material>
  <material name="green">
    <color rgba="0.0 0.8 0.0 1.0"/>
  </material>
  <material name="grey">
    <color rgba="0.2 0.2 0.2 1.0"/>
  </material>
  <material name="silver">
    <color rgba="0.9137254901960784 0.9137254901960784 0.8470588235294118 1.0"/>
  </material>
  <material name="orange">
    <color rgba="1.0 0.4235294117647059 0.0392156862745098 1.0"/>
  </material>
  <material name="brown">
    <color rgba="0.8705882352941177 0.8117647058823529 0.7647058823529411 1.0"/>
  </material>
  <material name="red">
    <color rgba="0.8 0.0 0.0 1.0"/>
  </material>
  <material name="white">
    <color rgba="1.0 1.0 1.0 1.0"/>
  </material>
  <link name="base_link">
    <visual>
      <origin rpy="0.0 0.0 0.0" xyz="0.0 0.0 0.0"/>
      <geometry>
        <box size="0.001 0.001 0.001"/>
      </geometry>
    </visual>
  </link>
  <joint name="R_palm_joint" type="fixed">
    <origin rpy="0.0 0.0 0.0" xyz="0.0 0.0 0.0"/>
    <parent link="base_link"/>
    <child link="R_palm"/>
  </joint>
  <link name="R_palm">
    <visual>
      <origin rpy="0 0 0" xyz="0 0 0"/>
      <geometry>
        <mesh filename="meshes/r_palm.STL"/>
      </geometry>
      <material name="silver"/>
    </visual>
    <collision>
      <origin rpy="0 0 0" xyz="0 0 0.00725"/>
      <geometry>
        <cylinder length="0.0145" radius="0.028"/>
      </geometry>
    </collision>
    <collision>
      <origin rpy="0 0 0" xyz="0 0 0.057"/>
      <geometry>
        <box size="0.04 0.082 0.085"/>
      </geometry>
    </collision>
    <inertial>
      <origin rpy="0 0 0" xyz="-0.0071151 0.0044599 0.0455754"/>
      <mass value="0.2175"/>
      <inertia ixx="0.00023334" ixy="4.25e-06" ixz="-2.03e-05" iyy="0.00020584" iyz="9.89e-06" izz="0.00012494"/>
    </inertial>
  </link>
  <!-- thumb  -->
  <joint name="R_thumb_roll_joint" type="revolute">
    <origin rpy="0 0 0" xyz="0 0.018529 0.046851"/>
    <parent link="R_palm"/>
    <child link="R_thumb_roll"/>
    <axis xyz="1 0 0"/>
    <limit effort="0.419" lower="-0.17453292519943295" upper="0.8726646259971648" velocity="0.164"/>
  </joint>
  <link name="R_thumb_roll">
    <visual>
      <origin rpy="0 0 0" xyz="0 0 0"/>
      <geometry>
        <mesh filename="meshes/r_thumb_roll.STL"/>
      </geometry>
      <material name="blue"/>
    </visual>
    <inertial>
      <origin rpy="0 0 0" xyz="0.018588 -0.0062386 0.0002106"/>
      <mass value="0.0179"/>
      <inertia ixx="3.64e-06" ixy="-5e-08" ixz="7e-08" iyy="2.68e-06" iyz="6e-08" izz="1.76e-06"/>
    </inertial>
  </link>
  <joint name="R_thumb_abad_joint" type="revolute">
    <origin rpy="0 0 0" xyz="0.020033 0.004292 0.00075"/>
    <parent link="R_thumb_roll"/>
    <child link="R_thumb_abad"/>
    <axis xyz="0 0 1"/>
    <limit effort="0.314" lower="-1.7453292519943295" upper="0" velocity="0.164"/>
  </joint>
  <link name="R_thumb_abad">
    <visual>
      <origin rpy="0 0 0" xyz="0 0 0"/>
      <geometry>
        <mesh filename="meshes/thumb_abad.STL"/>
      </geometry>
      <material name="blue"/>
    </visual>
    <inertial>
      <origin rpy="0 0 0" xyz="0.0 0.0120925 -0.0060829"/>
      <mass value="0.0061"/>
      <inertia ixx="1.21e-06" ixy="0.0" ixz="-1e-08" iyy="9.8e-07" iyz="-3e-08" izz="6e-07"/>
    </inertial>
  </link>
  <joint name="R_thumb_mcp_joint" type="revolute">
    <origin rpy="0 0 0" xyz="0 0.0265 -0.0058001"/>
    <parent link="R_thumb_abad"/>
    <child link="R_thumb_mcp"/>
    <axis xyz="1 0 0"/>
    <limit effort="1.764" lower="0" upper="0.8552113334772214" velocity="0.308"/>
  </joint>
  <link name="R_thumb_mcp">
    <visual>
      <origin rpy="0 0 0" xyz="0 0 0"/>
      <geometry>
        <mesh filename="meshes/thumb_mcp.STL"/>
      </geometry>
      <material name="brown"/>
    </visual>
    <collision>
      <origin rpy="0 0 0" xyz="0 0.0065 0.00237"/>
      <geometry>
        <box size="0.029 0.042 0.0325"/>
      </geometry>
    </collision>
    <inertial>
      <origin rpy="0 0 0" xyz="-1.45e-05 0.019045 0.0020161"/>
      <mass value="0.045"/>
      <inertia ixx="1.149e-05" ixy="0.0" ixz="1e-08" iyy="5.16e-06" iyz="-5.3e-07" izz="1.049e-05"/>
    </inertial>
  </link>
  <joint name="R_thumb_pip_joint" type="revolute">
    <origin rpy="0 0 0" xyz="0 0.036229 0.0026606"/>
    <parent link="R_thumb_mcp"/>
    <child link="R_thumb_pip"/>
    <axis xyz="1 0 0"/>
    <limit effort="1.764" lower="0" upper="1.1344640137963142" velocity="0.308"/>
    <mimic joint="R_thumb_mcp_joint" multiplier="0.5" offset="0"/>
    <!-- <mimic joint="R_thumb_mcp_joint" multiplier="1.33" offset="0"/> -->
  </joint>
  <link name="R_thumb_pip">
    <visual>
      <origin rpy="0 0 0" xyz="0 0 0"/>
      <geometry>
        <mesh filename="meshes/thumb_pip.STL"/>
      </geometry>
      <material name="white"/>
    </visual>
    <collision>
      <origin rpy="-0.2 0 0" xyz="0 0.0116 -0.0032"/>
      <geometry>
        <box size="0.019 0.035 0.0225"/>
      </geometry>
    </collision>
    <inertial>
      <origin rpy="0 0 0" xyz="0.0004121 0.0066398 -0.0025675"/>
      <mass value="0.0284"/>
      <inertia ixx="4.53e-06" ixy="1.2e-07" ixz="1.3e-07" iyy="2.5e-06" iyz="-5.8e-07" izz="4e-06"/>
    </inertial>
  </link>
  <joint name="R_thumb_dip_joint" type="revolute">
    <origin rpy="0 0 0" xyz="0 0.026054 -0.008672"/>
    <parent link="R_thumb_pip"/>
    <child link="R_thumb_dip"/>
    <axis xyz="1 0 0"/>
    <limit effort="1.764" lower="0" upper="1.1344640137963142" velocity="0.308"/>
    <mimic joint="R_thumb_mcp_joint" multiplier="0.5" offset="0"/>
    <!-- <mimic joint="R_thumb_mcp_joint" multiplier="1.3" offset="0"/> -->
  </joint>
  <link name="R_thumb_dip">
    <visual>
      <origin rpy="0 0 0" xyz="0 0 0"/>
      <geometry>
        <mesh filename="meshes/thumb_dip.STL"/>
      </geometry>
      <material name="white"/>
    </visual>
    <collision>
      <origin rpy="-1.8 0 0" xyz="0 0.0134 -0.0026"/>
      <geometry>
        <cylinder length="0.023" radius="0.011"/>
      </geometry>
    </collision>
    <inertial>
      <origin rpy="0 0 0" xyz="-0.0001343 0.0104003 -0.0042117"/>
      <mass value="0.011"/>
      <inertia ixx="1.1e-06" ixy="0.0" ixz="0.0" iyy="7.5e-07" iyz="-1.9e-07" izz="1.01e-06"/>
    </inertial>
  </link>
  <joint name="R_thumb_tip_joint" type="fixed">
    <origin rpy="0 0 0" xyz="0 0.02311 -0.01374"/>
    <parent link="R_thumb_dip"/>
    <child link="R_thumb_tip"/>
  </joint>
  <link name="R_thumb_tip">
    <visual>
      <origin rpy="0 0 0" xyz="0 0 0"/>
      <geometry>
        <sphere radius="1e-3"/>
      </geometry>
      <material name="white"/>
    </visual>
  </link>
  <!-- finger  -->
  <joint name="R_index_abad_joint" type="revolute">
    <origin rpy="0 0 0" xyz="-0.00069782 0.026958 0.094423"/>
    <parent link="R_palm"/>
    <child link="R_index_abad"/>
    <axis xyz="1 0 0"/>
    <limit effort="1.863" lower="-0.20943951023931953" upper="0" velocity="0.164"/>
  </joint>
  <link name="R_index_abad">
    <visual>
      <origin rpy="0 0 0" xyz="0 0 0"/>
      <geometry>
        <mesh filename="meshes/finger_abad.STL"/>
      </geometry>
      <material name="green"/>
    </visual>
    <inertial>
      <origin rpy="0 0 0" xyz="-0.0009337 -2.37e-05 0.0063625"/>
      <mass value="0.0349"/>
      <inertia ixx="6.74e-06" ixy="0.0" ixz="-3.3e-07" iyy="7.81e-06" iyz="0.0" izz="2.37e-06"/>
    </inertial>
  </link>
  
        y 
  <joint name="R_index_pip_joint" type="revolute">
    <origin rpy="0 0 0" xyz="0.001025 0 0.017575"/>
    <parent link="R_index_abad"/>
    <child link="R_index_pip"/>
    <axis xyz="0 1 0"/>
    <limit effort="1.764" lower="0" upper="1.5707963267948966" velocity="0.308"/>
  </joint>
  <link name="R_index_pip">
    <visual>
      <origin rpy="0 0 0" xyz="0 0 0"/>
      <geometry>
        <mesh filename="meshes/finger_pip.STL"/>
      </geometry>
      <material name="brown"/>
    </visual>
    <collision>
      <origin rpy="0 0 0" xyz="0 0 0.014"/>
      <geometry>
        <cylinder length="0.044" radius="0.01"/>
      </geometry>
    </collision>
    <inertial>
      <origin rpy="0 0 0" xyz="-0.0009312 -9.8e-06 0.0120489"/>
      <mass value="0.0125"/>
      <inertia ixx="3.16e-06" ixy="0.0" ixz="-3.5e-07" iyy="3.23e-06" iyz="0.0" izz="6.3e-07"/>
    </inertial>
  </link>
  <joint name="R_index_dip_joint" type="revolute">
    <origin rpy="0 0 0" xyz=" -0.0014266  0 0.036"/>
    <parent link="R_index_pip"/>
    <child link="R_index_dip"/>
    <axis xyz="0 1 0"/>
    <limit effort="1.764" lower="0" upper="1.8325957145940461" velocity="0.308"/>
    <!-- <mimic joint="R_index_pip_joint" multiplier="1.097" offset="0"/> -->
    <mimic joint="R_index_pip_joint" multiplier="0.3" offset="0"/>
  </joint>
  <link name="R_index_dip">
    <visual>
      <origin rpy="0 0 0" xyz="0 0 0"/>
      <geometry>
        <mesh filename="meshes/finger_dip.STL"/>
      </geometry>
      <material name="orange"/>
    </visual>
    <collision>
      <origin rpy="0 0 0" xyz="0 0 0.018"/>
      <geometry>
        <cylinder length="0.034" radius="0.007"/>
      </geometry>
    </collision>
    <inertial>
      <origin rpy="0 0 0" xyz="0.0002904 4.82e-05 0.0167403"/>
      <mass value="0.0047"/>
      <inertia ixx="7.6e-07" ixy="0.0" ixz="2e-08" iyy="7.7e-07" iyz="0.0" izz="1.6e-07"/>
    </inertial>
  </link>
  <joint name="R_index_tip_joint" type="fixed">
    <origin rpy="0 0 0" xyz="-0.00131 0 0.03841"/>
    <parent link="R_index_dip"/>
    <child link="R_index_tip"/>
  </joint>
  <link name="R_index_tip">
    <visual>
      <origin rpy="0 0 0" xyz="0 0 0"/>
      <geometry>
        <sphere radius="1e-3"/>
      </geometry>
      <material name="white"/>
    </visual>
  </link>
  <joint name="R_middle_abad_joint" type="fixed">
    <origin rpy="0 0 0" xyz="-0.0031978 0.0079501 0.096423"/>
    <parent link="R_palm"/>
    <child link="R_middle_abad"/>
  </joint>
  <link name="R_middle_abad">
    <visual>
      <origin rpy="0 0 0" xyz="0 0 0"/>
      <geometry>
        <mesh filename="meshes/finger_abad.STL"/>
      </geometry>
      <material name="green"/>
    </visual>
    <inertial>
      <origin rpy="0 0 0" xyz="-0.0009337 -2.37e-05 0.0063625"/>
      <mass value="0.0349"/>
      <inertia ixx="6.74e-06" ixy="0.0" ixz="-3.3e-07" iyy="7.81e-06" iyz="0.0" izz="2.37e-06"/>
    </inertial>
  </link>
  
        y 
  <joint name="R_middle_pip_joint" type="revolute">
    <origin rpy="0 0 0" xyz="0.001025 0 0.017575"/>
    <parent link="R_middle_abad"/>
    <child link="R_middle_pip"/>
    <axis xyz="0 1 0"/>
    <limit effort="1.764" lower="0" upper="1.5707963267948966" velocity="0.308"/>
  </joint>
  <link name="R_middle_pip">
    <visual>
      <origin rpy="0 0 0" xyz="0 0 0"/>
      <geometry>
        <mesh filename="meshes/finger_pip.STL"/>
      </geometry>
      <material name="brown"/>
    </visual>
    <collision>
      <origin rpy="0 0 0" xyz="0 0 0.014"/>
      <geometry>
        <cylinder length="0.044" radius="0.01"/>
      </geometry>
    </collision>
    <inertial>
      <origin rpy="0 0 0" xyz="-0.0009312 -9.8e-06 0.0120489"/>
      <mass value="0.0125"/>
      <inertia ixx="3.16e-06" ixy="0.0" ixz="-3.5e-07" iyy="3.23e-06" iyz="0.0" izz="6.3e-07"/>
    </inertial>
  </link>
  <joint name="R_middle_dip_joint" type="revolute">
    <origin rpy="0 0 0" xyz=" -0.0014266  0 0.036"/>
    <parent link="R_middle_pip"/>
    <child link="R_middle_dip"/>
    <axis xyz="0 1 0"/>
    <limit effort="1.764" lower="0" upper="1.8325957145940461" velocity="0.308"/>
    <mimic joint="R_middle_pip_joint" multiplier="0.3" offset="0"/>
    <!-- <mimic joint="R_middle_pip_joint" multiplier="1.097" offset="0"/> -->
  </joint>
  <link name="R_middle_dip">
    <visual>
      <origin rpy="0 0 0" xyz="0 0 0"/>
      <geometry>
        <mesh filename="meshes/finger_dip.STL"/>
      </geometry>
      <material name="orange"/>
    </visual>
    <collision>
      <origin rpy="0 0 0" xyz="0 0 0.018"/>
      <geometry>
        <cylinder length="0.034" radius="0.007"/>
      </geometry>
    </collision>
    <inertial>
      <origin rpy="0 0 0" xyz="0.0002904 4.82e-05 0.0167403"/>
      <mass value="0.0047"/>
      <inertia ixx="7.6e-07" ixy="0.0" ixz="2e-08" iyy="7.7e-07" iyz="0.0" izz="1.6e-07"/>
    </inertial>
  </link>
  <joint name="R_middle_tip_joint" type="fixed">
    <origin rpy="0 0 0" xyz="-0.00131 0 0.03841"/>
    <parent link="R_middle_dip"/>
    <child link="R_middle_tip"/>
  </joint>
  <link name="R_middle_tip">
    <visual>
      <origin rpy="0 0 0" xyz="0 0 0"/>
      <geometry>
        <sphere radius="1e-3"/>
      </geometry>
      <material name="white"/>
    </visual>
  </link>
  <joint name="R_ring_abad_joint" type="revolute">
    <origin rpy="0 0 0" xyz="-0.0021978 -0.01105 0.094423"/>
    <parent link="R_palm"/>
    <child link="R_ring_abad"/>
    <axis xyz="1 0 0"/>
    <limit effort="2.766" lower="0" upper="0.17453292519943295" velocity="0.164"/>
  </joint>
  <link name="R_ring_abad">
    <visual>
      <origin rpy="0 0 0" xyz="0 0 0"/>
      <geometry>
        <mesh filename="meshes/finger_abad.STL"/>
      </geometry>
      <material name="green"/>
    </visual>
    <inertial>
      <origin rpy="0 0 0" xyz="-0.0009337 -2.37e-05 0.0063625"/>
      <mass value="0.0349"/>
      <inertia ixx="6.74e-06" ixy="0.0" ixz="-3.3e-07" iyy="7.81e-06" iyz="0.0" izz="2.37e-06"/>
    </inertial>
  </link>
  
        y 
  <joint name="R_ring_pip_joint" type="revolute">
    <origin rpy="0 0 0" xyz="0.001025 0 0.017575"/>
    <parent link="R_ring_abad"/>
    <child link="R_ring_pip"/>
    <axis xyz="0 1 0"/>
    <limit effort="1.764" lower="0" upper="1.5707963267948966" velocity="0.308"/>
  </joint>
  <link name="R_ring_pip">
    <visual>
      <origin rpy="0 0 0" xyz="0 0 0"/>
      <geometry>
        <mesh filename="meshes/finger_pip.STL"/>
      </geometry>
      <material name="brown"/>
    </visual>
    <collision>
      <origin rpy="0 0 0" xyz="0 0 0.014"/>
      <geometry>
        <cylinder length="0.044" radius="0.01"/>
      </geometry>
    </collision>
    <inertial>
      <origin rpy="0 0 0" xyz="-0.0009312 -9.8e-06 0.0120489"/>
      <mass value="0.0125"/>
      <inertia ixx="3.16e-06" ixy="0.0" ixz="-3.5e-07" iyy="3.23e-06" iyz="0.0" izz="6.3e-07"/>
    </inertial>
  </link>
  <joint name="R_ring_dip_joint" type="revolute">
    <origin rpy="0 0 0" xyz=" -0.0014266  0 0.036"/>
    <parent link="R_ring_pip"/>
    <child link="R_ring_dip"/>
    <axis xyz="0 1 0"/>
    <limit effort="1.764" lower="0" upper="1.8325957145940461" velocity="0.308"/>
    <mimic joint="R_ring_pip_joint" multiplier="0.3" offset="0"/>
    <!-- <mimic joint="R_ring_pip_joint" multiplier="1.097" offset="0"/> -->
  </joint>
  <link name="R_ring_dip">
    <visual>
      <origin rpy="0 0 0" xyz="0 0 0"/>
      <geometry>
        <mesh filename="meshes/finger_dip.STL"/>
      </geometry>
      <material name="orange"/>
    </visual>
    <collision>
      <origin rpy="0 0 0" xyz="0 0 0.018"/>
      <geometry>
        <cylinder length="0.034" radius="0.007"/>
      </geometry>
    </collision>
    <inertial>
      <origin rpy="0 0 0" xyz="0.0002904 4.82e-05 0.0167403"/>
      <mass value="0.0047"/>
      <inertia ixx="7.6e-07" ixy="0.0" ixz="2e-08" iyy="7.7e-07" iyz="0.0" izz="1.6e-07"/>
    </inertial>
  </link>
  <joint name="R_ring_tip_joint" type="fixed">
    <origin rpy="0 0 0" xyz="-0.00131 0 0.03841"/>
    <parent link="R_ring_dip"/>
    <child link="R_ring_tip"/>
  </joint>
  <link name="R_ring_tip">
    <visual>
      <origin rpy="0 0 0" xyz="0 0 0"/>
      <geometry>
        <sphere radius="1e-3"/>
      </geometry>
      <material name="white"/>
    </visual>
  </link>
  <joint name="R_pinky_abad_joint" type="revolute">
    <origin rpy="0 0 0" xyz="-0.00069782 -0.03005 0.089423"/>
    <parent link="R_palm"/>
    <child link="R_pinky_abad"/>
    <axis xyz="1 0 0"/>
    <limit effort="3.393" lower="0" upper="0.20943951023931953" velocity="0.164"/>
  </joint>
  <link name="R_pinky_abad">
    <visual>
      <origin rpy="0 0 0" xyz="0 0 0"/>
      <geometry>
        <mesh filename="meshes/finger_abad.STL"/>
      </geometry>
      <material name="green"/>
    </visual>
    <inertial>
      <origin rpy="0 0 0" xyz="-0.0009337 -2.37e-05 0.0063625"/>
      <mass value="0.0349"/>
      <inertia ixx="6.74e-06" ixy="0.0" ixz="-3.3e-07" iyy="7.81e-06" iyz="0.0" izz="2.37e-06"/>
    </inertial>
  </link>
  
        y 
  <joint name="R_pinky_pip_joint" type="revolute">
    <origin rpy="0 0 0" xyz="0.001025 0 0.017575"/>
    <parent link="R_pinky_abad"/>
    <child link="R_pinky_pip"/>
    <axis xyz="0 1 0"/>
    <limit effort="1.764" lower="0" upper="1.5707963267948966" velocity="0.308"/>
  </joint>
  <link name="R_pinky_pip">
    <visual>
      <origin rpy="0 0 0" xyz="0 0 0"/>
      <geometry>
        <mesh filename="meshes/finger_pip.STL"/>
      </geometry>
      <material name="brown"/>
    </visual>
    <collision>
      <origin rpy="0 0 0" xyz="0 0 0.014"/>
      <geometry>
        <cylinder length="0.044" radius="0.01"/>
      </geometry>
    </collision>
    <inertial>
      <origin rpy="0 0 0" xyz="-0.0009312 -9.8e-06 0.0120489"/>
      <mass value="0.0125"/>
      <inertia ixx="3.16e-06" ixy="0.0" ixz="-3.5e-07" iyy="3.23e-06" iyz="0.0" izz="6.3e-07"/>
    </inertial>
  </link>
  <joint name="R_pinky_dip_joint" type="revolute">
    <origin rpy="0 0 0" xyz=" -0.0014266  0 0.036"/>
    <parent link="R_pinky_pip"/>
    <child link="R_pinky_dip"/>
    <axis xyz="0 1 0"/>
    <limit effort="1.764" lower="0" upper="1.8325957145940461" velocity="0.308"/>
    <!-- <mimic joint="R_pinky_pip_joint" multiplier="1.097" offset="0"/> -->
    <mimic joint="R_pinky_pip_joint" multiplier="0.3" offset="0"/>
  </joint>
  <link name="R_pinky_dip">
    <visual>
      <origin rpy="0 0 0" xyz="0 0 0"/>
      <geometry>
        <mesh filename="meshes/finger_dip.STL"/>
      </geometry>
      <material name="orange"/>
    </visual>
    <collision>
      <origin rpy="0 0 0" xyz="0 0 0.018"/>
      <geometry>
        <cylinder length="0.034" radius="0.007"/>
      </geometry>
    </collision>
    <inertial>
      <origin rpy="0 0 0" xyz="0.0002904 4.82e-05 0.0167403"/>
      <mass value="0.0047"/>
      <inertia ixx="7.6e-07" ixy="0.0" ixz="2e-08" iyy="7.7e-07" iyz="0.0" izz="1.6e-07"/>
    </inertial>
  </link>
  <joint name="R_pinky_tip_joint" type="fixed">
    <origin rpy="0 0 0" xyz="-0.00131 0 0.03841"/>
    <parent link="R_pinky_dip"/>
    <child link="R_pinky_tip"/>
  </joint>
  <link name="R_pinky_tip">
    <visual>
      <origin rpy="0 0 0" xyz="0 0 0"/>
      <geometry>
        <sphere radius="1e-3"/>
      </geometry>
      <material name="white"/>
    </visual>
  </link>
</robot>
